<?xml version="1.0" ?>
<!-- =================================================================================== -->
<!-- |    This document was autogenerated by xacro from /root/ros_ws/src/robot_urdf/urdf/m2wr_arm2.xacro | -->
<!-- |    EDITING THIS FILE BY HAND IS NOT RECOMMENDED                                 | -->
<!-- =================================================================================== -->
<robot name="m2wr">
    <material name="black">
        <color rgba="0.0 0.0 0.0 1.0" />
    </material>
    <material name="blue">
        <color rgba="0.203125 0.23828125 0.28515625 1.0" />
    </material>
    <material name="green">
        <color rgba="0.0 0.8 0.0 1.0" />
    </material>
    <material name="grey">
        <color rgba="0.2 0.2 0.2 1.0" />
    </material>
    <material name="orange">
        <color rgba="1.0 0.423529411765 0.0392156862745 1.0" />
    </material>
    <material name="brown">
        <color rgba="0.870588235294 0.811764705882 0.764705882353 1.0" />
    </material>
    <material name="red">
        <color rgba="0.80078125 0.12890625 0.1328125 1.0" />
    </material>
    <material name="white">
        <color rgba="1.0 1.0 1.0 1.0" />
    </material>
    <gazebo reference="base_link">
        <material>Gazebo/Orange</material>
    </gazebo>
    <gazebo reference="link_left_wheel">
        <material>Gazebo/Blue</material>
    </gazebo>
    <gazebo reference="link_right_wheel">
        <material>Gazebo/Blue</material>
    </gazebo>
    <gazebo reference="arm_base_link">
        <material>Gazebo/Red</material>
    </gazebo>
    <gazebo reference="arm_link_01">
        <material>Gazebo/Red</material>
    </gazebo>
    <gazebo reference="arm_link_02">
        <material>Gazebo/Red</material>
    </gazebo>
    <gazebo reference="arm_link_03">
        <material>Gazebo/Red</material>
    </gazebo>
    <gazebo reference="cluedo_link">
        <material>Gazebo/Red</material>
    </gazebo>
    <gazebo reference="right_grip_link">
        <material>Gazebo/White</material>
    </gazebo>
    <gazebo reference="left_grip_link">
        <material>Gazebo/White</material>
    </gazebo>
    <gazebo reference="arm_joint_02">
        <provideFeedback>true</provideFeedback>
    </gazebo>
    <!-- The ft_sensor plugin -->
    <gazebo>
        <plugin filename="libgazebo_ros_ft_sensor.so" name="ft_sensor">
            <updateRate>100.0</updateRate>
            <topicName>ft_sensor_topic</topicName>
            <jointName>arm_joint_02</jointName>
        </plugin>
    </gazebo>
    <gazebo>
        <plugin filename="libgazebo_ros_diff_drive.so" name="differential_drive_controller">
            <legacyMode>true</legacyMode>
            <alwaysOn>true</alwaysOn>
            <updateRate>20</updateRate>
            <leftJoint>joint_left_wheel</leftJoint>
            <rightJoint>joint_right_wheel</rightJoint>
            <wheelSeparation>0.3</wheelSeparation>
            <wheelDiameter>0.2</wheelDiameter>
            <torque>0.1</torque>
            <commandTopic>cmd_vel</commandTopic>
            <odometryTopic>odom</odometryTopic>
            <odometryFrame>odom</odometryFrame>
            <robotBaseFrame>base_link</robotBaseFrame>
            <rosDebugLevel>na</rosDebugLevel>
            <publishWheelTF>true</publishWheelTF>
            <publishWheelJointState>true</publishWheelJointState>
            <wheelAcceleration>0</wheelAcceleration>
            <wheelTorque>5</wheelTorque>
            <odometrySource>1</odometrySource>
            <publishTf>1</publishTf>
        </plugin>
    </gazebo>
    <gazebo reference="laser">
        <sensor name="head_hokuyo_sensor" type="ray">
            <pose>0 0 0 0 0 0</pose>
            <visualize>false</visualize>
            <update_rate>20</update_rate>
            <ray>
                <scan>
                    <horizontal>
                        <samples>720</samples>
                        <resolution>1</resolution>
                        <min_angle>-1.570796</min_angle>
                        <max_angle>1.570796</max_angle>
                    </horizontal>
                </scan>
                <range>
                    <min>0.10</min>
                    <max>10.0</max>
                    <resolution>0.01</resolution>
                </range>
                <noise>
                    <type>gaussian</type>
                    <mean>0.0</mean>
                    <stddev>0.01</stddev>
                </noise>
            </ray>
            <plugin filename="libgazebo_ros_laser.so" name="gazebo_ros_head_hokuyo_controller">
                <topicName>scan</topicName>
                <frameName>laser</frameName>
            </plugin>
        </sensor>
    </gazebo>
    <gazebo>
        <plugin filename="libgazebo_ros_control.so" name="gazebo_ros_control">
            <!--robotNamespace>m2wr</robotNamespace-->
            <robotSimType>gazebo_ros_control/DefaultRobotHWSim</robotSimType>
            <legacyModeNS>true</legacyModeNS>
        </plugin>
    </gazebo>
    <link name="base_link">
        <!-- pose and inertial -->
        <pose>0 0 0.1 0 0 0</pose>
        
<inertial>
            <mass value="5" />
            <origin rpy="0 0 0" xyz="0 0 0.1" />
            <inertia ixx="0.0395416666667" ixy="0" ixz="0" iyy="0.106208333333" iyz="0" izz="0.106208333333" />
        </inertial>

        <collision name="collision_chassis">
            <geometry>
                <box size="0.5 0.3 0.07" />
            </geometry>
        </collision>
        <visual>
            <origin rpy="0 0 0" xyz="0 0 0" />
            <geometry>
                <box size="0.5 0.3 0.07" />
            </geometry>
            <material name="blue" />
        </visual>
        <!-- caster front -->
        <collision name="caster_front_collision">
            <origin rpy=" 0 0 0" xyz="0.35 0 -0.05" />
            <geometry>
                <sphere radius="0.05" />
            </geometry>
            <surface>
                <friction>
                    <ode>
                        <mu>0</mu>
                        <mu2>0</mu2>
                        <slip1>1.0</slip1>
                        <slip2>1.0</slip2>
                    </ode>
                </friction>
            </surface>
        </collision>
        <visual name="caster_front_visual">
            <origin rpy=" 0 0 0" xyz="0.2 0 -0.05" />
            <geometry>
                <sphere radius="0.05" />
            </geometry>
        </visual>
    </link>
    <!-- Create wheels -->
    <link name="link_right_wheel">
        
<inertial>
            <mass value="0.2" />
            <origin rpy="0 1.5707 1.5707" xyz="0 0 0" />
            <inertia ixx="0.000526666666667" ixy="0" ixz="0" iyy="0.000526666666667" iyz="0" izz="0.001" />
        </inertial>

        <collision name="link_right_wheel_collision">
            <origin rpy="0 1.5707 1.5707" xyz="0 0 0" />
            <geometry>
                <cylinder length="0.04" radius="0.1" />
            </geometry>
        </collision>
        <visual name="link_right_wheel_visual">
            <origin rpy="0 1.5707 1.5707" xyz="0 0 0" />
            <geometry>
                <cylinder length="0.04" radius="0.1" />
            </geometry>
        </visual>
    </link>
    <link name="link_left_wheel">
        
<inertial>
            <mass value="0.2" />
            <origin rpy="0 1.5707 1.5707" xyz="0 0 0" />
            <inertia ixx="0.000526666666667" ixy="0" ixz="0" iyy="0.000526666666667" iyz="0" izz="0.001" />
        </inertial>

        <collision name="link_right_wheel_collision">
            <origin rpy="0 1.5707 1.5707" xyz="0 0 0" />
            <geometry>
                <cylinder length="0.04" radius="0.1" />
            </geometry>
        </collision>
        <visual name="link_left_wheel_visual">
            <origin rpy="0 1.5707 1.5707" xyz="0 0 0" />
            <geometry>
                <cylinder length="0.04" radius="0.1" />
            </geometry>
        </visual>
    </link>
    <joint name="joint_right_wheel" type="continuous">
        <origin rpy="0 0 0" xyz="-0.05 0.15 0" />
        <child link="link_right_wheel" />
        <parent link="base_link" />
        <axis rpy="0 0 0" xyz="0 1 0" />
        <limit effort="10000" velocity="1000" />
        <joint_properties damping="1.0" friction="1.0" />
    </joint>
    <joint name="joint_left_wheel" type="continuous">
        <origin rpy="0 0 0" xyz="-0.05 -0.15 0" />
        <child link="link_left_wheel" />
        <parent link="base_link" />
        <axis rpy="0 0 0" xyz="0 1 0" />
        <limit effort="10000" velocity="1000" />
        <joint_properties damping="1.0" friction="1.0" />
    </joint>
    <link name="laser">
        
<inertial>
            <origin rpy="0 0 0" xyz="0 0 0" />
            <mass value="1" />
            <inertia ixx="0.0014583333333333334" ixy="0" ixz="0" iyy="0.0014583333333333334" iyz="0" izz="0.0012500000000000002" />
        </inertial>

        <visual>
            <origin rpy="0 0 0" xyz="0 0 0" />
            <geometry>
                <cylinder length="0.1" radius="0.05" />
            </geometry>
            <material name="white" />
        </visual>
        <collision>
            <origin rpy="0 0 0" xyz="0 0 0" />
            <geometry>
                <cylinder length="0.1" radius="0.05" />
            </geometry>
        </collision>
    </link>
    <joint name="joint_laser" type="fixed">
        <origin rpy="0 0 0" xyz="0.3 0 0.05" />
        <parent link="base_link" />
        <child link="laser" />
    </joint>
    <!--arm definition -->
    <link name="arm_base_link">
        
<inertial>
            <mass value="0.1" />
            <origin rpy="0 0 0" xyz="0 0 0" />
            <inertia ixx="0.0000416666667" ixy="0" ixz="0" iyy="0.0000416666667" iyz="0" izz="0.0000416666667" />
        </inertial>

        <collision>
            <origin rpy="0 0 0" xyz="0 0 0" />
            <geometry>
                <box size="0.1 0.1 0.1" />
            </geometry>
        </collision>
        <visual>
            <origin rpy="0 0 0" xyz="0 0 0" />
            <geometry>
                <box size="0.1 0.1 0.1" />
            </geometry>
            <material name="red" />
        </visual>
    </link>
    <joint name="arm_base_to_base" type="fixed">
        <origin rpy="0 0 0" xyz="0 0 0.085" />
        <parent link="base_link" />
        <child link="arm_base_link" />
    </joint>
    <link name="arm_link_01">
        
<inertial>
            <mass value="0.025" />
            <origin rpy="0 0 0" xyz="0 0 0" />
            <inertia ixx="0.000010279" ixy="0" ixz="0" iyy="0.000010279" iyz="0" izz="0.000007225" />
        </inertial>

        <collision>
            <origin rpy="0 0 0" xyz="0 0 0" />
            <geometry>
                <cylinder length="0.4" radius="0.04" />
            </geometry>
        </collision>
        <visual>
            <origin rpy="0 0 0" xyz="0 0 0" />
            <geometry>
                <cylinder length="0.4" radius="0.04" />
            </geometry>
            <material name="red" />
        </visual>
    </link>
    <joint name="arm_joint_01" type="revolute">
        <axis xyz="0 0 1" />
        <limit effort="1000.0" lower="-3.14" upper="3.14" velocity="0.2" />
        <origin rpy="0 0 0" xyz="0 0 0.15" />
        <parent link="arm_base_link" />
        <child link="arm_link_01" />
    </joint>
    <link name="arm_link_02">
        
<inertial>
            <mass value="0.015" />
            <origin rpy="0 0 0" xyz="0 0 0" />
            <inertia ixx="0.000010279" ixy="0" ixz="0" iyy="0.000010279" iyz="0" izz="0.000007225" />
        </inertial>

        <collision>
            <origin rpy="0 0 0" xyz="0 0 0.2" />
            <geometry>
                <cylinder length="0.4" radius="0.04" />
            </geometry>
        </collision>
        <visual>
            <origin rpy="0 0 0" xyz="0 0 0.2" />
            <geometry>
                <cylinder length="0.4" radius="0.04" />
            </geometry>
            <material name="red" />
        </visual>
    </link>
    <joint name="arm_joint_02" type="revolute">
        <axis xyz="1 0 0" />
        <limit effort="1000.0" lower="-1.8" upper="1.8" velocity="0.2" />
        <origin rpy="0 0 0" xyz="0 0 0.2" />
        <parent link="arm_link_01" />
        <child link="arm_link_02" />
    </joint>
    <link name="arm_link_03">
        
<inertial>
            <mass value="0.015" />
            <origin rpy="0 0 0" xyz="0 0 0" />
            <inertia ixx="0.000010279" ixy="0" ixz="0" iyy="0.000010279" iyz="0" izz="0.000007225" />
        </inertial>

        <collision>
            <origin rpy="0 0 0" xyz="0 0 0.2" />
            <geometry>
                <cylinder length="0.4" radius="0.04" />
            </geometry>
        </collision>
        <visual>
            <origin rpy="0 0 0" xyz="0 0 0.2" />
            <geometry>
                <cylinder length="0.4" radius="0.04" />
            </geometry>
            <material name="red" />
        </visual>
    </link>
    <joint name="arm_joint_03" type="revolute">
        <axis xyz="1 0 0" />
        <limit effort="1000.0" lower="-1.8" upper="1.8" velocity="0.2" />
        <origin rpy="0 0 0" xyz="0 0 0.4" />
        <parent link="arm_link_02" />
        <child link="arm_link_03" />
    </joint>
    <link name="cluedo_link">
        
<inertial>
            <mass value="0.015" />
            <origin rpy="0 0 0" xyz="0 0 0" />
            <inertia ixx="0.000010279" ixy="0" ixz="0" iyy="0.000010279" iyz="0" izz="0.000007225" />
        </inertial>

        <collision>
            <origin rpy="0 0 1.57" xyz="0 0 0.04" />
            <geometry>
                <box size="0.034 0.2 0.08" />
            </geometry>
        </collision>
        <visual>
            <origin rpy="0 0 1.57" xyz="0 0 0.04" />
            <geometry>
                <box size="0.034 0.2 0.08" />
            </geometry>
            <material name="red" />
        </visual>
    </link>
    <joint name="arm_joint_04" type="revolute">
        <axis xyz="1 0 0" />
        <limit effort="1000.0" lower="-1.8" upper="1.8" velocity="0.5" />
        <origin rpy="0 0 0" xyz="0 0 0.4" />
        <parent link="arm_link_03" />
        <child link="cluedo_link" />
    </joint>

    <link name="right_grip_link">
        
<inertial>
            <mass value="0.01" />
            <origin rpy="0 0 0" xyz="0 0 0" />
            <inertia ixx="0.000010279" ixy="0" ixz="0" iyy="0.000010279" iyz="0" izz="0.000007225" />
        </inertial>

        <collision>
            <origin rpy="0 3.1415 -1.57" xyz="-0.032 0.048 0.04" />
            <geometry>
                <box size="0.06 0.02 0.08" />
            </geometry>
        </collision>
        <visual>
            <origin rpy="0 3.1415 -1.57" xyz="-0.032 0.048 0.04" />
            <geometry>
                <box size="0.06 0.02 0.08" />
            </geometry>
            <material name="white" />
        </visual>
    </link>
    <joint name="right_grip_joint" type="prismatic">
        <axis xyz="1 0 0" />
        <limit effort="1000.0" lower="-0.04" upper="0.035" velocity="6.5" />
        <origin rpy="0 0 0" xyz="-0.015 0 0.0" />
        <parent link="cluedo_link" />
        <child link="right_grip_link" />
    </joint>
    <link name="left_grip_link">
        
<inertial>
            <mass value="0.01" />
            <origin rpy="0 0 0" xyz="0 0 0" />
            <inertia ixx="0.000010279" ixy="0" ixz="0" iyy="0.000010279" iyz="0" izz="0.000007225" />
        </inertial>

        <collision>
            <origin rpy="0 3.1415 -1.57" xyz="0.06 0.048 0.04" />
            <geometry>
                <box size="0.06 0.02 0.08" />
            </geometry>
        </collision>
        <visual>
            <origin rpy="0 3.1415 -1.57" xyz="0.06 0.048 0.04" />
            <geometry>
                <box size="0.06 0.02 0.08" />
            </geometry>
            <material name="white" />
        </visual>
    </link>
    <joint name="left_grip_joint" type="prismatic">
        <axis xyz="1 0 0" />
        <limit effort="1000.0" lower="-0.035" upper="0.04" velocity="6.5" />
        <origin rpy="0 0 0" xyz="-0.015 0 0.0" />
        <parent link="cluedo_link" />
        <child link="left_grip_link" />
    </joint>
    
<transmission name="arm_joint_01_trans">
        <type>transmission_interface/SimpleTransmission</type>
        <joint name="arm_joint_01">
            <hardwareInterface>hardware_interface/EffortJointInterface</hardwareInterface>
        </joint>
        <actuator name="motor1">
            <hardwareInterface>hardware_interface/EffortJointInterface</hardwareInterface>
            <mechanicalInterface>1</mechanicalInterface>
        </actuator>
    </transmission>
    <transmission name="arm_joint_02_trans">
        <type>transmission_interface/SimpleTransmission</type>
        <joint name="arm_joint_02">
            <hardwareInterface>hardware_interface/EffortJointInterface</hardwareInterface>
        </joint>
        <actuator name="motor2">
            <hardwareInterface>hardware_interface/EffortJointInterface</hardwareInterface>
            <mechanicalInterface>1</mechanicalInterface>
        </actuator>
    </transmission>
    <transmission name="arm_joint_03_trans">
        <type>transmission_interface/SimpleTransmission</type>
        <joint name="arm_joint_03">
            <hardwareInterface>hardware_interface/EffortJointInterface</hardwareInterface>
        </joint>
        <actuator name="motor3">
            <hardwareInterface>hardware_interface/EffortJointInterface</hardwareInterface>
            <mechanicalInterface>1</mechanicalInterface>
        </actuator>
    </transmission>
    <transmission name="arm_joint_04_trans">
        <type>transmission_interface/SimpleTransmission</type>
        <joint name="arm_joint_04">
            <hardwareInterface>hardware_interface/EffortJointInterface</hardwareInterface>
        </joint>
        <actuator name="motor4">
            <hardwareInterface>hardware_interface/EffortJointInterface</hardwareInterface>
            <mechanicalInterface>1</mechanicalInterface>
        </actuator>
    </transmission>
    
    <transmission name="left_grip_trans">
        <type>transmission_interface/SimpleTransmission</type>
        <joint name="left_grip_joint">
            <hardwareInterface>hardware_interface/EffortJointInterface</hardwareInterface>
        </joint>
        <actuator name="motor5">
            <hardwareInterface>hardware_interface/EffortJointInterface</hardwareInterface>
            <mechanicalInterface>1</mechanicalInterface>
        </actuator>
    </transmission>
    <transmission name="right_grip_trans">
        <type>transmission_interface/SimpleTransmission</type>
        <joint name="right_grip_joint">
            <hardwareInterface>hardware_interface/EffortJointInterface</hardwareInterface>
        </joint>
        <actuator name="motor6">
            <hardwareInterface>hardware_interface/EffortJointInterface</hardwareInterface>
            <mechanicalInterface>1</mechanicalInterface>
        </actuator>
    </transmission>
    <transmission name="trans_joint_right_wheel">
        <type>transmission_interface/SimpleTransmission</type>
        <joint name="joint_right_wheel">
            <hardwareInterface>hardware_interface/EffortJointInterface</hardwareInterface>
        </joint>
        <actuator name="joint_right_wheel_motor">
            <hardwareInterface>hardware_interface/EffortJointInterface</hardwareInterface>
            <mechanicalReduction>1</mechanicalReduction>
        </actuator>
    </transmission>
    <transmission name="trans_joint_left_wheel">
        <type>transmission_interface/SimpleTransmission</type>
        <joint name="joint_left_wheel">
            <hardwareInterface>hardware_interface/EffortJointInterface</hardwareInterface>
        </joint>
        <actuator name="joint_left_wheel_motor">
            <hardwareInterface>hardware_interface/EffortJointInterface</hardwareInterface>
            <mechanicalReduction>1</mechanicalReduction>
        </actuator>
    </transmission>
    <transmission name="trans_arm_joint_01">
        <type>transmission_interface/SimpleTransmission</type>
        <joint name="arm_joint_01">
            <hardwareInterface>hardware_interface/EffortJointInterface</hardwareInterface>
        </joint>
        <actuator name="arm_joint_01_motor">
            <hardwareInterface>hardware_interface/EffortJointInterface</hardwareInterface>
            <mechanicalReduction>1</mechanicalReduction>
        </actuator>
    </transmission>
    <transmission name="trans_arm_joint_02">
        <type>transmission_interface/SimpleTransmission</type>
        <joint name="arm_joint_02">
            <hardwareInterface>hardware_interface/EffortJointInterface</hardwareInterface>
        </joint>
        <actuator name="arm_joint_02_motor">
            <hardwareInterface>hardware_interface/EffortJointInterface</hardwareInterface>
            <mechanicalReduction>1</mechanicalReduction>
        </actuator>
    </transmission>
    <transmission name="trans_arm_joint_03">
        <type>transmission_interface/SimpleTransmission</type>
        <joint name="arm_joint_03">
            <hardwareInterface>hardware_interface/EffortJointInterface</hardwareInterface>
        </joint>
        <actuator name="arm_joint_03_motor">
            <hardwareInterface>hardware_interface/EffortJointInterface</hardwareInterface>
            <mechanicalReduction>1</mechanicalReduction>
        </actuator>
    </transmission>
    <transmission name="trans_arm_joint_04">
        <type>transmission_interface/SimpleTransmission</type>
        <joint name="arm_joint_04">
            <hardwareInterface>hardware_interface/EffortJointInterface</hardwareInterface>
        </joint>
        <actuator name="arm_joint_04_motor">
            <hardwareInterface>hardware_interface/EffortJointInterface</hardwareInterface>
            <mechanicalReduction>1</mechanicalReduction>
        </actuator>
    </transmission>
    <transmission name="trans_right_grip_joint">
        <type>transmission_interface/SimpleTransmission</type>
        <joint name="right_grip_joint">
            <hardwareInterface>hardware_interface/EffortJointInterface</hardwareInterface>
        </joint>
        <actuator name="right_grip_joint_motor">
            <hardwareInterface>hardware_interface/EffortJointInterface</hardwareInterface>
            <mechanicalReduction>1</mechanicalReduction>
        </actuator>
    </transmission>
    <transmission name="trans_left_grip_joint">
        <type>transmission_interface/SimpleTransmission</type>
        <joint name="left_grip_joint">
            <hardwareInterface>hardware_interface/EffortJointInterface</hardwareInterface>
        </joint>
        <actuator name="left_grip_joint_motor">
            <hardwareInterface>hardware_interface/EffortJointInterface</hardwareInterface>
            <mechanicalReduction>1</mechanicalReduction>
        </actuator>
    </transmission>
    <gazebo>
        <plugin name="gazebo_ros_control" filename="libgazebo_ros_control.so">
            <robotNamespace>/</robotNamespace>
        </plugin>
    </gazebo>
    
    
  <link name="camera_link">
	    <collision>
	      <origin xyz="0 0 1" rpy="0 0 0"/>
	      <geometry>
		<box size="0.0001 0.0001 0.00001"/>
	      </geometry>
	    </collision>
	    <visual>
	      <origin xyz="0 0 0.025" rpy="0 0 0"/>
	      <geometry>
		<box size="0.000005 0.00005 0.0005"/>
	      </geometry>
	      <material name="red">
		<color rgba="1 0 0 1"/>
	      </material>
	    </visual>
	    <inertial>
	      <mass value="1e-5" />
	      <origin xyz="0 0 0" rpy="0 0 0"/>
	      <inertia ixx="1e-6" ixy="0" ixz="0" iyy="1e-6" iyz="0" izz="1e-6" />
	    </inertial> 
  </link>
  
  <joint name="camera_joint" type="fixed">
	    <axis xyz="0 1 0" />
	    <origin xyz="0.28 0 2" rpy="0 0 0"/>
	    <parent link="base_link"/>
	    <child link="camera_link"/> 
	 </joint>
	 
   <!--link name="cameradepth_link">
    <collision>
      <origin xyz="0 0 0" rpy="0 0 0"/>
      <geometry>
        <box size="0.05 0.05 0.05"/>
      </geometry>
    </collision>

    <visual>
      <origin xyz="0 0 0" rpy="0 0 0"/>
      <geometry>
    <box size="0.05 0.05 0.05"/>
      </geometry>
      <material name="orange"/>
    </visual>

    <inertial> 
      <origin xyz="0 0 0" rpy="0 0 0"/> 
      <mass value="0.1"/> 
      <inertia ixx="1e-6" ixy="0" ixz="0" iyy="1e-6" iyz="0" izz="1e-6" />
    </inertial>
  </link>

	 <joint name="camera_depth_joint" type="fixed">
    <origin xyz="0 0 0" rpy="-1.57 0 -1.57 "/>
    <parent link="camera_link"/>
    <child link="cameradepth_link"/>
  </joint-->
  
  
  

  <gazebo>
    <plugin filename="libgazebo_ros_diff_drive.so" name="differential_drive_controller">
      <legacyMode>true</legacyMode>
      <alwaysOn>true</alwaysOn>
      <updateRate>1000</updateRate>
      <leftJoint>joint_left_wheel</leftJoint>
      <rightJoint>joint_right_wheel</rightJoint>
      <wheelSeparation>0.2</wheelSeparation>
      <wheelDiameter>0.2</wheelDiameter>
      <torque>0.1</torque>
      <commandTopic>cmd_vel</commandTopic>
      <odometryTopic>odom</odometryTopic>
      <odometryFrame>odom</odometryFrame>
      <robotBaseFrame>base_link</robotBaseFrame>
    </plugin>
  </gazebo>
  
  <!-- ros_control plugin -->
  <gazebo>
    <plugin name="gazebo_ros_control" filename="libgazebo_ros_control.so">
     <!-- <robotNamespace>/robot</robotNamespace> -->
      <legacyModeNS>true</legacyModeNS>
    </plugin>
  </gazebo>

   <!-- hokuyo -->
<gazebo reference="camera_link">
  <sensor name="rgbd" type="depth">
    <update_rate>20</update_rate>
    <camera>
      <horizontal_fov>1.047198</horizontal_fov>
      <image>
        <width>640</width>
        <height>480</height>
        <format>R8G8B8</format>
      </image>
      <clip>
        <near>0.05</near>
        <far>3</far>
      </clip>
    </camera>
    <plugin name="camera_controller" filename="libgazebo_ros_openni_kinect.so">
      <baseline>0.2</baseline>
      <alwaysOn>true</alwaysOn>
      <updateRate>1.0</updateRate>
      <cameraName>camera_ir</cameraName>
      <imageTopicName>/camera/color/image_raw</imageTopicName>
      <cameraInfoTopicName>/camera/color/camera_info</cameraInfoTopicName>
      <depthImageTopicName>/camera/depth/image_raw</depthImageTopicName>
      <depthImageInfoTopicName>/camera/depth/camera_info</depthImageInfoTopicName>
      <pointCloudTopicName>/camera/depth/points</pointCloudTopicName>
      <frameName>cameradepth_link</frameName>
      <pointCloudCutoff>0.5</pointCloudCutoff>
      <pointCloudCutoffMax>3.0</pointCloudCutoffMax>
      <distortionK1>0.00000001</distortionK1>
      <distortionK2>0.00000001</distortionK2>
      <distortionK3>0.00000001</distortionK3>
      <distortionT1>0.00000001</distortionT1>
      <distortionT2>0.00000001</distortionT2>
      <CxPrime>0</CxPrime>
      <Cx>0</Cx>
      <Cy>0</Cy>
      <focalLength>0</focalLength>
      <hackBaseline>0</hackBaseline>
    </plugin>
  </sensor>
</gazebo>

  
    
</robot>
